<bug>
          <bug_id>1581</bug_id>
          
          <creation_ts>2008-11-12 14:17:00 +0100</creation_ts>
          <short_desc>Generator shows error, if you try to include a widget from contrib</short_desc>
          <delta_ts>2014-03-03 15:25:07 +0100</delta_ts>
          <reporter_accessible>1</reporter_accessible>
          <cclist_accessible>1</cclist_accessible>
          <classification_id>1</classification_id>
          <classification>Unclassified</classification>
          <product>framework</product>
          <component>tool.generator</component>
          <version>0.8.1</version>
          <rep_platform>All</rep_platform>
          <op_sys>All</op_sys>
          <bug_status>CLOSED</bug_status>
          <resolution>INVALID</resolution>
          
          
          
          
          
          <priority>P4</priority>
          <bug_severity>normal</bug_severity>
          <target_milestone>0.8.3</target_milestone>
          
          
          
          <everconfirmed>1</everconfirmed>
          <reporter name="Yuecel Beser">yuecel_beser</reporter>
          <assigned_to name="Thomas Herchenroeder">thron7</assigned_to>
          
          <qa_contact name="qooxdoo bugs mailing list">qooxdoo-bugs</qa_contact>
          <cf_browser>---</cf_browser>
          

      

      

      

          <long_desc isprivate="0">
            <commentid>6273</commentid>
            <who name="Yuecel Beser">yuecel_beser</who>
            <bug_when>2008-11-12 14:17:56 +0100</bug_when>
            <thetext>============================================================================
    INITIALIZING: TOOLBOX
============================================================================
&gt;&gt;&gt; Configuration: config.json
&gt;&gt;&gt; Jobs: source
&gt;&gt;&gt; Resolving jobs...
&gt;&gt;&gt; Resolving macros...
&gt;&gt;&gt; Resolving libs/manifests...
  - Downloading contrib: UploadWidget/trunk
Traceback (most recent call last):
  File &quot;C:\Python25\lib\pdb.py&quot;, line 1193, in main
    pdb._runscript(mainpyfile)
  File &quot;C:\Python25\lib\pdb.py&quot;, line 1118, in _runscript
    self.run(statement, globals=globals_, locals=locals_)
  File &quot;C:\Python25\lib\bdb.py&quot;, line 366, in run
    exec cmd in globals, locals
  File &quot;&lt;string&gt;&quot;, line 1, in &lt;module&gt;
  File &quot;../../tool/bin/generator.py&quot;, line 141, in &lt;module&gt;
    main()
  File &quot;../../tool/bin/generator.py&quot;, line 126, in main
    config.resolveLibs(expandedjobs)
  File &quot;C:\Dokumente und Einstellungen\ybeser\workspace\qooxdoo.trunk\tool\pylib\generator\config\Config.py&quot;, line 49
in resolveLibs
    self._download_contrib(newlib, contrib, contribCachePath)
  File &quot;C:\Dokumente und Einstellungen\ybeser\workspace\qooxdoo.trunk\tool\pylib\generator\config\Config.py&quot;, line 54
in _download_contrib
    dloader.download(contrib, contribCache)
  File &quot;C:\dokumente und einstellungen\ybeser\workspace\qooxdoo.trunk\tool\pylib\generator\action\ContribLoader.py&quot;,
e 67, in download
    open(revisionFile, &quot;w&quot;).write(externalRevision)
TypeError: argument 1 must be string or read-only character buffer, not None
Uncaught exception. Entering post mortem debugging
Running &#39;cont&#39; or &#39;step&#39; will restart the program
&gt; c:\dokumente und einstellungen\ybeser\workspace\qooxdoo.trunk\tool\pylib\generator\action\contribloader.py(67)downl
()
-&gt; open(revisionFile, &quot;w&quot;).write(externalRevision)
(Pdb) where
  c:\python25\lib\bdb.py(371)run()
-&gt; sys.settrace(None)
  &lt;string&gt;(1)&lt;module&gt;()
  c:\dokumente und einstellungen\ybeser\workspace\qooxdoo.trunk\tool\bin\generator.py(22)&lt;module&gt;()
-&gt; import sys, os, optparse, string, types, pprint
  c:\dokumente und einstellungen\ybeser\workspace\qooxdoo.trunk\tool\bin\generator.py(126)main()
-&gt; config.resolveLibs(expandedjobs)
  c:\dokumente und einstellungen\ybeser\workspace\qooxdoo.trunk\tool\pylib\generator\config\config.py(493)resolveLibs
-&gt; self._download_contrib(newlib, contrib, contribCachePath)
  c:\dokumente und einstellungen\ybeser\workspace\qooxdoo.trunk\tool\pylib\generator\config\config.py(541)_download_c
rib()
-&gt; dloader.download(contrib, contribCache)
&gt; c:\dokumente und einstellungen\ybeser\workspace\qooxdoo.trunk\tool\pylib\generator\action\contribloader.py(67)downl
()
-&gt; open(revisionFile, &quot;w&quot;).write(externalRevision)
(Pdb) q
Post mortem debugger finished. The ../../tool/bin/generator.py will be restarted
&gt; c:\dokumente und einstellungen\ybeser\workspace\qooxdoo.trunk\tool\bin\generator.py(22)&lt;module&gt;()
-&gt; import sys, os, optparse, string, types, pprint
(Pdb) q</thetext>
          </long_desc>
          <long_desc isprivate="0">
            <commentid>9511</commentid>
            <who name="Fabian Jakobs">fabian.jakobs</who>
            <bug_when>2009-04-23 10:48:23 +0200</bug_when>
            <thetext>@Thomas have you looked at this issue? Is it still valid?</thetext>
          </long_desc>
          <long_desc isprivate="0">
            <commentid>9526</commentid>
            <who name="Thomas Herchenroeder">thron7</who>
            <bug_when>2009-04-23 11:46:33 +0200</bug_when>
            <thetext>No, I haven&#39;t looked at it, but it could still be valid. I doesn&#39;t seem to be a 
Toolbox-specific issue, maybe more related to platform (win32) and/or specific 
paths in use, but generic to contrib downloading. So I think it&#39;s still worth 
looking at.</thetext>
          </long_desc>
          <long_desc isprivate="0">
            <commentid>11601</commentid>
            <who name="Thomas Herchenroeder">thron7</who>
            <bug_when>2009-08-26 19:20:25 +0200</bug_when>
            <thetext>down prio for now. haven&#39;t heard of any recent case of this.</thetext>
          </long_desc>
          <long_desc isprivate="0">
            <commentid>11660</commentid>
            <who name="Andreas Ecker">qooxdoo</who>
            <bug_when>2009-08-27 17:10:49 +0200</bug_when>
            <thetext>Thomas, I also think it is questionable that this bug is still valid. If it were, one could expect similar reports. As it&#39;s unlikely to have this bug report reproduced by the reporterin the original setup, lets close this bug as INVALID.
</thetext>
          </long_desc>
          <long_desc isprivate="0">
            <commentid>38634</commentid>
            <who name="Martin Wittemann">martin.wittemann</who>
            <bug_when>2014-03-03 15:25:07 +0100</bug_when>
            <thetext>Closed all bugs already shipped with a release.</thetext>
          </long_desc>
      
      

    </bug>