<bug>
          <bug_id>2922</bug_id>
          
          <creation_ts>2009-10-13 11:13:00 +0200</creation_ts>
          <short_desc>Maximum recursion depth exceeded during dependency checking</short_desc>
          <delta_ts>2014-03-03 15:19:05 +0100</delta_ts>
          <reporter_accessible>1</reporter_accessible>
          <cclist_accessible>1</cclist_accessible>
          <classification_id>1</classification_id>
          <classification>Unclassified</classification>
          <product>framework</product>
          <component>tool.generator</component>
          <version>0.8.3</version>
          <rep_platform>All</rep_platform>
          <op_sys>All</op_sys>
          <bug_status>CLOSED</bug_status>
          <resolution>FIXED</resolution>
          
          
          
          
          
          <priority>P3</priority>
          <bug_severity>blocker</bug_severity>
          <target_milestone>1.0-beta1</target_milestone>
          
          
          
          <everconfirmed>1</everconfirmed>
          <reporter name="Thomas Herchenroeder">thron7</reporter>
          <assigned_to name="Thomas Herchenroeder">thron7</assigned_to>
          <cc>alexander.steitz</cc>
    
    <cc>matthias.braun</cc>
          <qa_contact name="qooxdoo bugs mailing list">qooxdoo-bugs</qa_contact>
          <cf_browser>---</cf_browser>
          

      

      

      

          <long_desc isprivate="0">
            <commentid>13150</commentid>
            <who name="Thomas Herchenroeder">thron7</who>
            <bug_when>2009-10-13 11:13:16 +0200</bug_when>
            <thetext>A Python runtime error occurs since the recent change in dependency tracking 
(cf. bug#2376) with the mailclient when doing &#39;ant script-source&#39;. I wasn&#39;t 
able to repro it (tried with various Python versions of the 2.5 and 2.6 
flavors), but Alex and Markus could. The error is that the Python recursion 
limit is exceeded, I will post a complete stack trace in a separate comment.</thetext>
          </long_desc>
          <long_desc isprivate="0">
            <commentid>13151</commentid>
            <who name="Thomas Herchenroeder">thron7</who>
            <bug_when>2009-10-13 11:16:55 +0200</bug_when>
            <thetext>add CC&#39;s</thetext>
          </long_desc>
          <long_desc isprivate="0">
            <commentid>13152</commentid>
            <who name="Thomas Herchenroeder">thron7</who>
            <bug_when>2009-10-13 11:22:00 +0200</bug_when>
            <thetext>Patched tool/bin/generator.py with

  sys.setrecursionlimit(1500)

I could not reproduce the problem, although I tried several times. I think this 
patch might be temporary, but as I see no way to reproduce the problem, I don&#39;t 
know where to attack it and verify that another solution works. Therefore, the 
patch might stay in, which wouldn&#39;t be a big issue either, I think (although it 
feels a bit like a work-around).

With  r20341.</thetext>
          </long_desc>
          <long_desc isprivate="0">
            <commentid>14635</commentid>
            <who name="Andreas Ecker">qooxdoo</who>
            <bug_when>2009-11-24 20:16:14 +0100</bug_when>
            <thetext>mass renaming of 0.9 target to 1.0-beta1</thetext>
          </long_desc>
          <long_desc isprivate="0">
            <commentid>36337</commentid>
            <who name="Martin Wittemann">martin.wittemann</who>
            <bug_when>2014-03-03 15:19:05 +0100</bug_when>
            <thetext>Closed all bugs already shipped with a release.</thetext>
          </long_desc>
      
      

    </bug>