<bug>
          <bug_id>4823</bug_id>
          
          <creation_ts>2011-03-21 10:34:00 +0100</creation_ts>
          <short_desc>Some internal listeners form the data binding are not removed</short_desc>
          <delta_ts>2011-03-22 08:01:11 +0100</delta_ts>
          <reporter_accessible>1</reporter_accessible>
          <cclist_accessible>1</cclist_accessible>
          <classification_id>1</classification_id>
          <classification>Unclassified</classification>
          <product>framework</product>
          <component>core.databinding</component>
          <version>1.3</version>
          <rep_platform>All</rep_platform>
          <op_sys>All</op_sys>
          <bug_status>CLOSED</bug_status>
          <resolution>FIXED</resolution>
          
          
          
          
          
          <priority>P2</priority>
          <bug_severity>minor</bug_severity>
          <target_milestone>1.3.1</target_milestone>
          
          
          
          <everconfirmed>1</everconfirmed>
          <reporter name="Christian Hagendorn">christian.hagendorn</reporter>
          <assigned_to name="Martin Wittemann">martin.wittemann</assigned_to>
          
          <qa_contact name="Martin Wittemann">martin.wittemann</qa_contact>
          <cf_browser>---</cf_browser>
          

      

      

      

          <long_desc isprivate="0">
            <commentid>23424</commentid>
            <who name="Christian Hagendorn">christian.hagendorn</who>
            <bug_when>2011-03-21 10:34:52 +0100</bug_when>
            <thetext>If the binding doesn&#39;t work, it could happen that the internal listeners for the chain are not removed. This cases a error when the originally data structure is modified.

Here a code snipped to reproduce the issue:

var o = qx.data.marshal.Json.createModel([{a: 10}, {}, {}]);
var l = new qx.ui.basic.Label(&quot;affe&quot;);
this.getRoot().add(l);

try {
  o.bind(&quot;[1].a&quot;, l, &quot;value&quot;);
} catch (ex) {
  console.log(&quot;!!!!!!!! exception&quot;);
}

// An exception occurs
o.shift();</thetext>
          </long_desc>
          <long_desc isprivate="0">
            <commentid>23426</commentid>
            <who name="Martin Wittemann">martin.wittemann</who>
            <bug_when>2011-03-21 10:40:46 +0100</bug_when>
            <thetext>Added a try catch block and remove the added listeners in the catch block.

trunk: r25841
1.3.x: r25842</thetext>
          </long_desc>
      
      

    </bug>