<bug>
          <bug_id>6776</bug_id>
          
          <creation_ts>2012-09-05 10:53:00 +0200</creation_ts>
          <short_desc>Better error logging in case of _createChildControl fails</short_desc>
          <delta_ts>2014-03-03 15:26:48 +0100</delta_ts>
          <reporter_accessible>1</reporter_accessible>
          <cclist_accessible>1</cclist_accessible>
          <classification_id>1</classification_id>
          <classification>Unclassified</classification>
          <product>framework</product>
          <component>desktop.core</component>
          <version>master</version>
          <rep_platform>All</rep_platform>
          <op_sys>All</op_sys>
          <bug_status>CLOSED</bug_status>
          <resolution>FIXED</resolution>
          
          
          
          
          
          <priority>P3</priority>
          <bug_severity>enhancement</bug_severity>
          <target_milestone>3.0</target_milestone>
          
          
          
          <everconfirmed>1</everconfirmed>
          <reporter name="Uwe Stahl">uwe.stahl</reporter>
          <assigned_to name="Daniel Wagner">daniel.wagner</assigned_to>
          
          <qa_contact name="Martin Wittemann">martin.wittemann</qa_contact>
          <cf_browser>---</cf_browser>
          

      

      

      

          <long_desc isprivate="0">
            <commentid>30602</commentid>
            <who name="Uwe Stahl">uwe.stahl</who>
            <bug_when>2012-09-05 10:53:25 +0200</bug_when>
            <thetext>Our error logging database contains the following log entries:
  qx.ui.core.Widget._createChildControl threw error: Access denied

We are not able to reproduce this issue, although several users have this problem.

Therefore we would suggest to improve the error logging done by the class qx.ui.core.Widget:

qx.Class.define(&quot;qx.ui.core.Widget&quot;,
  _createChildControl : function(id) {
    } catch (exc) {
      this.error(&quot;qx.ui.core.Widget._createChildControl threw error:&quot;, exc); 

I would suggest that the id (child-control-id) is also logged as part of the error message:
      this.error(&quot;qx.ui.core.Widget._createChildControl(&quot; + id + &quot;) threw error:&quot;, exc); 

All the other &quot;this.error()&quot; calls inside the function Widget._createChildControl add the id to the error message.

Would it also be possible to add the classname to the error message? It may happen that several different classes are using the same child-control-id.</thetext>
          </long_desc>
          <long_desc isprivate="0">
            <commentid>32931</commentid>
            <who name="Daniel Wagner">daniel.wagner</who>
            <bug_when>2013-06-13 11:59:00 +0200</bug_when>
            <thetext>I don&#39;t think framework classes should catch exceptions and replace them with log messages as it makes debugging needlessly hard. The decision whether or not an exception breaks the application should remain with the application developer.

Nevertheless, improving the error message is a good idea. I&#39;ve modified _createChildControl so that it catches any exceptions in the _createChildControlImpl call, amends the message and then re-throws the error. 

Messages now look like this:
Exception while creating child control &#39;someId&#39; of widget MyWidget[40-0]: &lt;original error message&gt;

Fixed with 109fddc (master)</thetext>
          </long_desc>
          <long_desc isprivate="0">
            <commentid>39240</commentid>
            <who name="Martin Wittemann">martin.wittemann</who>
            <bug_when>2014-03-03 15:26:48 +0100</bug_when>
            <thetext>Closed all bugs already shipped with a release.</thetext>
          </long_desc>
      
      

    </bug>