<bug>
          <bug_id>7090</bug_id>
          
          <creation_ts>2012-12-11 13:04:00 +0100</creation_ts>
          <short_desc>Improve error message if port of local source-server is occupied</short_desc>
          <delta_ts>2014-03-03 15:25:24 +0100</delta_ts>
          <reporter_accessible>1</reporter_accessible>
          <cclist_accessible>1</cclist_accessible>
          <classification_id>1</classification_id>
          <classification>Unclassified</classification>
          <product>framework</product>
          <component>tool.generator</component>
          <version>unspecified</version>
          <rep_platform>All</rep_platform>
          <op_sys>All</op_sys>
          <bug_status>CLOSED</bug_status>
          <resolution>FIXED</resolution>
          
          
          
          
          
          <priority>P3</priority>
          <bug_severity>normal</bug_severity>
          <target_milestone>3.0</target_milestone>
          <dependson>7032</dependson>
          
          
          <everconfirmed>1</everconfirmed>
          <reporter name="Andreas Ecker">qooxdoo</reporter>
          <assigned_to name="Thomas Herchenroeder">thron7</assigned_to>
          
          <qa_contact name="Richard Sternagel">richard.sternagel</qa_contact>
          <cf_browser>---</cf_browser>
          

      

      

      

          <long_desc isprivate="0">
            <commentid>31699</commentid>
            <who name="Andreas Ecker">qooxdoo</who>
            <bug_when>2012-12-11 13:04:13 +0100</bug_when>
            <thetext>Example: run the &#39;source-server&#39; job, but the configured port is occupied:

*******************************************************************************************

$ ./generate.py source-server

----------------------------------------------------------------------------
    Initializing: qxappwatch
----------------------------------------------------------------------------
&gt;&gt;&gt; Processing configuration

----------------------------------------------------------------------------
    Executing: source-server
----------------------------------------------------------------------------
&lt;class &#39;socket.error&#39;&gt; :Traceback (most recent call last):
  File &quot;generator.py&quot;, line 266, in &lt;module&gt;
    print &gt;&gt; sys.stderr, el[:300]
TypeError: &#39;int&#39; object is not subscriptable

*******************************************************************************************

The user should get an easy-to-understand message for the regular &#39;source-server&#39; invocation.
Btw, if started with the &#39;-s&#39; flag, it indeed says (after the verbose stacktrace info) &quot;Address already in use&quot;.</thetext>
          </long_desc>
          <long_desc isprivate="0">
            <commentid>31739</commentid>
            <who name="Thomas Herchenroeder">thron7</who>
            <bug_when>2012-12-14 15:13:13 +0100</bug_when>
            <thetext>With fixing bug#7093, this is also solved for all practical reasons.</thetext>
          </long_desc>
          <long_desc isprivate="0">
            <commentid>38732</commentid>
            <who name="Martin Wittemann">martin.wittemann</who>
            <bug_when>2014-03-03 15:25:24 +0100</bug_when>
            <thetext>Closed all bugs already shipped with a release.</thetext>
          </long_desc>
      
      

    </bug>