<bug>
          <bug_id>7106</bug_id>
          
          <creation_ts>2012-12-20 13:38:00 +0100</creation_ts>
          <short_desc>Pretty print exception in generator.py</short_desc>
          <delta_ts>2014-03-03 08:47:25 +0100</delta_ts>
          <reporter_accessible>1</reporter_accessible>
          <cclist_accessible>1</cclist_accessible>
          <classification_id>1</classification_id>
          <classification>Unclassified</classification>
          <product>framework</product>
          <component>tool.generator</component>
          <version>2.1</version>
          <rep_platform>All</rep_platform>
          <op_sys>Windows</op_sys>
          <bug_status>RESOLVED</bug_status>
          <resolution>LATER</resolution>
          
          
          
          
          
          <priority>P3</priority>
          <bug_severity>normal</bug_severity>
          <target_milestone>unspecified</target_milestone>
          
          
          
          <everconfirmed>1</everconfirmed>
          <reporter>krejci</reporter>
          <assigned_to name="Richard Sternagel">richard.sternagel</assigned_to>
          
          <qa_contact name="Richard Sternagel">richard.sternagel</qa_contact>
          <cf_browser>---</cf_browser>
          

      

      

      

          <long_desc isprivate="0">
            <commentid>31784</commentid>
            <who name="">krejci</who>
            <bug_when>2012-12-20 13:38:41 +0100</bug_when>
            <thetext>We have just recently updated project to version 2.1 from 2.0. So far was everything ok and running pretty-print was without issues. Suddenly i updated from our Git repository and running pretty-print again gives following output:

&gt;&gt;&gt; Pretty-printing code...
  - Pretty-printing files:  60%&lt;type &#39;exceptions.IOError&#39;&gt; :Traceback (most recent call last):
  File &quot;C:\@workspace\NEN\qooxdoo\tool\bin\generator.py&quot;, line 266, in &lt;module&gt;
    print &gt;&gt; sys.stderr, el[:300]
TypeError: &#39;int&#39; object is not subscriptable

Really hard to say from this error what is happening and what file caused it. So I went into generator.py and modified that a bit to throw whole exception. Than run the job again:

&gt;&gt;&gt; Pretty-printing code...
  - Pretty-printing files:  60%Traceback (most recent call last):
  File &quot;C:\@workspace\NEN\qooxdoo\tool\bin\generator.py&quot;, line 243, in &lt;module&gt;
    main()
  File &quot;C:\@workspace\NEN\qooxdoo\tool\bin\generator.py&quot;, line 226, in main
    generatorObj.run()
  File &quot;C:\@workspace\NEN\qooxdoo\tool\pylib\generator\Generator.py&quot;, line 500,in run
    self._codeGenerator.runPrettyPrinting(self._classesObj)
  File &quot;C:\@workspace\NEN\qooxdoo\tool\pylib\generator\code\CodeGenerator.py&quot;, line 1054, in runPrettyPrinting
    filetool.save(self._classes[classId].path, compiled)
  File &quot;C:\@workspace\NEN\qooxdoo\tool\pylib\misc\filetool.py&quot;, line 85, in save

    outputFile = codecs.open(filePath, encoding=encoding, mode=&quot;w&quot;, errors=&quot;replace&quot;)
  File &quot;C:\Python27\lib\codecs.py&quot;, line 881, in open
    file = __builtin__.open(filename, mode, buffering)
IOError: [Errno 13] Permission denied: u&#39;C:\\@workspace\\NEN\\app\\source\\class
\\nen\\widget\\tooltiptable\\rowrenderer\\RoleRenderer.js&#39;

Not sure what caused the issue with permission. I had removed file and made checkout on that and than it worked again.

Reason for this bug report is mostly about making that error tell me more. This way it hides important information. I don&#39;t know Python, so hard to tell, what&#39;s going on there.</thetext>
          </long_desc>
          <long_desc isprivate="0">
            <commentid>35900</commentid>
            <who name="Martin Wittemann">martin.wittemann</who>
            <bug_when>2014-03-03 08:47:25 +0100</bug_when>
            <thetext>Move open issues to RESOLVED â€“ LATER, whose last comment is older than a year.</thetext>
          </long_desc>
      
      

    </bug>