<bug>
          <bug_id>7309</bug_id>
          
          <creation_ts>2013-03-20 14:01:00 +0100</creation_ts>
          <short_desc>Unable to build on shared folder of VirtualBox</short_desc>
          <delta_ts>2013-12-16 12:45:29 +0100</delta_ts>
          <reporter_accessible>1</reporter_accessible>
          <cclist_accessible>1</cclist_accessible>
          <classification_id>1</classification_id>
          <classification>Unclassified</classification>
          <product>framework</product>
          <component>tool.generator</component>
          <version>2.1.1</version>
          <rep_platform>All</rep_platform>
          <op_sys>Linux</op_sys>
          <bug_status>RESOLVED</bug_status>
          <resolution>WONTFIX</resolution>
          
          
          
          
          
          <priority>P3</priority>
          <bug_severity>major</bug_severity>
          <target_milestone>unspecified</target_milestone>
          
          
          
          <everconfirmed>1</everconfirmed>
          <reporter name="Michael Wieland">qooxdoo</reporter>
          <assigned_to name="Thomas Herchenroeder">thron7</assigned_to>
          
          <qa_contact name="Richard Sternagel">richard.sternagel</qa_contact>
          <cf_browser>---</cf_browser>
          

      

      

      

          <long_desc isprivate="0">
            <commentid>32491</commentid>
            <who name="Michael Wieland">qooxdoo</who>
            <bug_when>2013-03-20 14:01:17 +0100</bug_when>
            <thetext>I&#39;m using a Debian 6 VM in VirtualBox on a Windows 7 host.

I&#39;ve shared a directory on my Windows 7 system using the VirtualBox shared folders to the VM and mounted the share as vboxsf to /var/www.

The qooxdoo SDK is in /var/www/qooxdoo. The qooxdoo projects are also on that /var/www vboxsf mountpoint.

But once I try to run the generate.py of one project, I get the following error:

Traceback (most recent call last):
  File &quot;/var/www/qooxdoo/tool/bin/generator.py&quot;, line 27, in &lt;module&gt;
    from generator.Generator import Generator
  File &quot;/var/www/qooxdoo/tool/pylib/generator/Generator.py&quot;, line 28, in &lt;module&gt;
    import graph
  File &quot;/var/www/qooxdoo/tool/pylib/graph/__init__.py&quot;, line 64, in &lt;module&gt;
    from classes import *
  File &quot;/var/www/qooxdoo/tool/pylib/graph/classes/__init__.py&quot;, line 40, in &lt;module&gt;
    from Graph import graph
  File &quot;/var/www/qooxdoo/tool/pylib/graph/classes/Graph.py&quot;, line 33, in &lt;module&gt;
    from graph.algorithms import *
  File &quot;/var/www/qooxdoo/tool/pylib/graph/classes/graph.py&quot;, line 33, in &lt;module&gt;
    from graph.algorithms import *
ImportError: No module named algorithms

I can build my project just fine if I copy qooxdoo and the project to another location on the VM&#39;s hard disk.

Seems to be a bug with network file systems in the generator of qooxdoo.</thetext>
          </long_desc>
          <long_desc isprivate="0">
            <commentid>32492</commentid>
            <who name="Thomas Herchenroeder">thron7</who>
            <bug_when>2013-03-20 14:44:12 +0100</bug_when>
            <thetext>I think this has nothing to do with qooxdoo. As the submodule folders and files 
are actually there, and can be found if you are on local file systems, it is 
nothing we can fix. The qooxdoo code just uses the normal Python &#39;import&#39; 
facility. If that fails due to issues with the vboxsf implementation maybe the 
Python core developers can help. How many other cases did you come across where 
you attempted to load Python modules from the vboxsf file system?!</thetext>
          </long_desc>
      
      

    </bug>