<bug>
          <bug_id>8167</bug_id>
          
          <creation_ts>2014-03-10 16:13:00 +0100</creation_ts>
          <short_desc>&quot;generate.py lint&quot; is not finding lint warning while &quot;generate.py api&quot; does</short_desc>
          <delta_ts>2014-03-28 08:04:53 +0100</delta_ts>
          <reporter_accessible>1</reporter_accessible>
          <cclist_accessible>1</cclist_accessible>
          <classification_id>1</classification_id>
          <classification>Unclassified</classification>
          <product>framework</product>
          <component>tool.generator</component>
          <version>master</version>
          <rep_platform>All</rep_platform>
          <op_sys>All</op_sys>
          <bug_status>RESOLVED</bug_status>
          <resolution>FIXED</resolution>
          
          
          
          
          
          <priority>P3</priority>
          <bug_severity>normal</bug_severity>
          <target_milestone>3.5.1</target_milestone>
          
          
          
          <everconfirmed>1</everconfirmed>
          <reporter>romeo.kenfacktsakem</reporter>
          <assigned_to name="Richard Sternagel">richard.sternagel</assigned_to>
          <cc>alexander.steitz</cc>
          <qa_contact name="Richard Sternagel">richard.sternagel</qa_contact>
          <cf_browser>---</cf_browser>
          

      

      

      

          <long_desc isprivate="0">
            <commentid>39709</commentid>
            <who name="">romeo.kenfacktsakem</who>
            <bug_when>2014-03-10 16:13:21 +0100</bug_when>
            <thetext>I have a lint issue (non declared variable) in the class &quot;qx.ui.website.Table&quot;.
The issue cannot be found when i run &quot;generate.py lint&quot; from the framework folder, but when i run &quot;generate.py api&quot;. all lint issues are detected.</thetext>
          </long_desc>
          <long_desc isprivate="0">
            <commentid>39797</commentid>
            <who name="Alexander Steitz">alexander.steitz</who>
            <bug_when>2014-03-26 16:15:36 +0100</bug_when>
            <thetext>Just checked out the issue a bit more ... the warning of &quot;./generate.py api&quot; is *not* rooted from a lint check.

The api job does check for global symbols in order to create infos for the libaries / top-level namespaces. 

Nevertheless, the &quot;lint&quot; job should stumble upon a variable which pollutes the global namespace. Looks like a regression to me.</thetext>
          </long_desc>
          <long_desc isprivate="0">
            <commentid>39803</commentid>
            <who name="Richard Sternagel">richard.sternagel</who>
            <bug_when>2014-03-27 18:54:10 +0100</bug_when>
            <thetext>This is a regression.

The function checking for global symbols itself worked but during the lint check it was curried [1] and the currying wasn&#39;t working correctly. It always returned the last (wrapped) function instead of the result. The (uncalled) function then always evaluated to True within a bool expression. So no global symbol was unknown and no warning was shown.

master: 6441d1b178c6f37abfa0ddc9b70415218c405400
branch_3_5_x: f432a4bca6421496eabb59784615aef3d2c7e517

[1] http://en.wikipedia.org/wiki/Currying</thetext>
          </long_desc>
      
      

    </bug>